<?xml version='1.0'?>
<sdf version='1.6'>
  <model name='NuBot_Pumbaa_v2'>
    <static>false</static>
    <allow_auto_disable>1</allow_auto_disable>

    <!--base_link-->
    <link name='base_link'>
      <pose frame=''>0 0 0 0 0 0</pose>
      <inertial>
        <pose frame=''>0 0 0 0 0 0</pose>
        <mass>20</mass>
        <inertia>
          <ixx>0.203664</ixx>
          <ixy>0</ixy>
          <ixz>0</ixz>
          <iyy>0.136197</iyy>
          <iyz>0</iyz>
          <izz>0.319921</izz>
        </inertia>
      </inertial>
      <self_collide>0</self_collide>
      <gravity>1</gravity>
      <kinematic>0</kinematic>
      <enable_wind>0</enable_wind>

      <!-- <collision name='base_link_collision'>
        <pose frame=''>0 0 0 0 0 0</pose>
        <laser_retro>0</laser_retro>
        <max_contacts>10</max_contacts>
        <geometry>
          <mesh>
            <scale>1 1 1</scale>
            <uri>model://NuBot_Pumbaa_v2/meshes/base_link.STL</uri>
          </mesh>
        </geometry>
        <surface>
          <friction>
            <ode>
              <mu>1</mu>
              <mu2>1</mu2>
              <fdir1>0 1 0</fdir1>
              <slip1>0</slip1>
              <slip2>0</slip2>
            </ode>
            <torsional>
              <coefficient>1</coefficient>
              <patch_radius>0</patch_radius>
              <surface_radius>0</surface_radius>
              <use_patch_radius>1</use_patch_radius>
              <ode>
                <slip>0</slip>
              </ode>
            </torsional>
          </friction>
          <bounce>
            <restitution_coefficient>0</restitution_coefficient>
            <threshold>1e+06</threshold>
          </bounce>
          <contact>
            <collide_without_contact>0</collide_without_contact>
            <collide_without_contact_bitmask>1</collide_without_contact_bitmask>
            <collide_bitmask>1</collide_bitmask>
            <ode>
              <soft_cfm>0</soft_cfm>
              <soft_erp>0.2</soft_erp>
              <kp>1e+13</kp>
              <kd>1</kd>
              <max_vel>0.01</max_vel>
              <min_depth>0</min_depth>
            </ode>
          </contact>
        </surface>
      </collision> -->
      <collision name='base_link_collision_1'>
        <max_contacts>10</max_contacts>
        <pose frame=''>0.276 0 0 1.5708 0 0</pose>
        <geometry>
          <cylinder>
            <radius>0.07</radius>
            <length>0.11</length>
          </cylinder>
        </geometry>
        <surface>
          <friction>
            <ode>
              <mu>1</mu>
              <mu2>1</mu2>
              <fdir1>0 1 0</fdir1>
            </ode>
          </friction>
        </surface>
      </collision>
      <collision name='base_link_collision_2'>
        <max_contacts>10</max_contacts>
        <pose frame=''>-0.276 0 0 1.5708 0 0</pose>
        <geometry>
          <cylinder>
            <radius>0.07</radius>
            <length>0.11</length>
          </cylinder>
        </geometry>
        <surface>
          <friction>
            <ode>
              <mu>1</mu>
              <mu2>1</mu2>
              <fdir1>0 1 0</fdir1>
            </ode>
          </friction>
        </surface>
      </collision>
      <collision name='base_link_collision'>
        <max_contacts>10</max_contacts>
        <pose frame=''>0 0 0 1.5708 0 1.5708</pose>
        <geometry>
          <box>
            <size>0.11 0.14 0.552</size>
          </box>
        </geometry>
        <surface>
          <friction>
            <ode>
              <mu>1</mu>
              <mu2>1</mu2>
              <fdir1>0 1 0</fdir1>
            </ode> 
          </friction>
        </surface>
      </collision>
      <!-- <collision name='base_link_fixed_joint_lump__vive_link_collision_3'>
        <pose frame=''>0.16175 0 0.138 0 0 0</pose>
        <geometry>
          <mesh>
            <scale>1 1 1</scale>
            <uri>model://NuBot_Pumbaa_v2/meshes/vive_link.STL</uri>
          </mesh>
        </geometry>
      </collision> -->
      <visual name='base_link_visual'>
        <pose frame=''>0 0 0 0 0 0</pose>
        <geometry>
          <mesh>
            <scale>1 1 1</scale>
            <uri>model://NuBot_Pumbaa_v2/meshes/base_link.STL</uri>
          </mesh>
        </geometry>
      </visual>
      <visual name='base_link_vive_link_visual'>
        <pose frame=''>0.16175 0 0.138 0 0 0</pose>
        <geometry>
          <mesh>
            <scale>1 1 1</scale>
            <uri>model://NuBot_Pumbaa_v2/meshes/vive_link.STL</uri>
          </mesh>
        </geometry>
      </visual>
    </link>

    <!--left_track-->
    <link name='left_track_link'>
      <pose frame=''>0 0.14 0 0 0 0</pose>
      <inertial>
        <pose frame=''>0 0 0 0 0 0</pose>
        <mass>10</mass>
        <inertia>
          <ixx>0.15</ixx>
          <ixy>0</ixy>
          <ixz>0</ixz>
          <iyy>0.9</iyy>
          <iyz>0</iyz>
          <izz>0.9</izz>
        </inertia>
      </inertial>>
      <gravity>1</gravity>
      <kinematic>0</kinematic>
      <self_collide>0</self_collide>
      <enable_wind>0</enable_wind>

      <visual name='left_track_visual'>
        <pose frame=''>0 -0.14 0 0 0 0</pose>
        <geometry>
          <mesh>
            <scale>1 1 1</scale>
            <uri>model://NuBot_Pumbaa_v2/meshes/left_track_link.STL</uri>
          </mesh>
        </geometry>>
      </visual>
      <collision name='left_track_collision_1'>
        <max_contacts>10</max_contacts>
        <pose frame=''>0.276 0 0 1.5708 0 0</pose>
        <geometry>
          <cylinder>
            <radius>0.09</radius>
            <length>0.18</length>
          </cylinder>
        </geometry>
        <surface>
          <friction>
            <ode>
              <mu>0.7</mu>
              <mu2>150</mu2>
              <fdir1>0 1 0</fdir1>
            </ode>
          </friction>
        </surface>
      </collision>
      <collision name='left_track_collision_2'>
        <max_contacts>10</max_contacts>
        <pose frame=''>-0.276 0 0 1.5708 0 0</pose>
        <geometry>
          <cylinder>
            <radius>0.09</radius>
            <length>0.18</length>
          </cylinder>
        </geometry>
        <surface>
          <friction>
            <ode>
              <mu>0.7</mu>
              <mu2>150</mu2>
              <fdir1>0 1 0</fdir1>
            </ode>
          </friction>
        </surface>
      </collision>
      <collision name='left_track_collision'>
        <max_contacts>10</max_contacts>
        <pose frame=''>0 0 0 1.5708 0 1.5708</pose>
        <geometry>
          <box>
            <size>0.18 0.18 0.552</size>
          </box>
        </geometry>
        <surface>
          <friction>
            <ode>
              <mu>0.7</mu>
              <mu2>150</mu2>
              <fdir1>0 1 0</fdir1>
            </ode> 
          </friction>
        </surface>
      </collision>
    </link>

    <!--right_track-->
    <link name='right_track_link'>
      <pose frame=''>0 -0.14 0 0 0 0</pose>
      <inertial>
        <pose frame=''>0 0 0 0 0 0</pose>
        <mass>10</mass>
        <inertia>
          <ixx>0.15</ixx>
          <ixy>0</ixy>
          <ixz>0</ixz>
          <iyy>0.9</iyy>
          <iyz>0</iyz>
          <izz>0.9</izz>
        </inertia>
      </inertial>
      <gravity>1</gravity>
      <kinematic>0</kinematic>
      <self_collide>0</self_collide>
      <enable_wind>0</enable_wind>

      <visual name='right_track_visual'>
        <pose frame=''>0 0.14 0 0 0 0</pose>
        <geometry>
          <mesh>
            <scale>1 1 1</scale>
            <uri>model://NuBot_Pumbaa_v2/meshes/right_track_link.STL</uri>
          </mesh>
        </geometry>
      </visual>
      <collision name='right_track_collision_1'>
        <max_contacts>10</max_contacts>
        <pose frame=''>0.276 0 0 1.5708 0 0</pose>
        <geometry>
          <cylinder>
            <radius>0.09</radius>
            <length>0.18</length>
          </cylinder>
        </geometry>
        <surface>
          <friction>
            <ode>
              <mu>0.7</mu>
              <mu2>150</mu2>
              <fdir1>0 1 0</fdir1>
            </ode>
          </friction>
        </surface>
      </collision>
      <collision name='right_track_collision'>
        <max_contacts>10</max_contacts>
        <pose frame=''>0 0 0 1.5708 0 1.5708</pose>
        <geometry>
          <box>
            <size>0.18 0.18 0.552</size>
          </box>
        </geometry>
        <surface>
          <friction>
            <ode>
              <mu>0.7</mu>
              <mu2>150</mu2>
              <fdir1>0 1 0</fdir1>
            </ode>
          </friction>
        </surface>
      </collision>
      <collision name='right_track_collision_2'>
        <max_contacts>10</max_contacts>
        <pose frame=''>-0.276 0 0 1.5708 0 0</pose>
        <geometry>
          <cylinder>
            <radius>0.09</radius>
            <length>0.18</length>
          </cylinder>
        </geometry>
        <surface>
          <friction>
            <ode>
              <mu>0.7</mu>
              <mu2>150</mu2>
              <fdir1>0 1 0</fdir1>
            </ode>
          </friction>
        </surface>
      </collision>
    </link>

    <!--main_track joints-->
    <joint name='left_track_joint' type='fixed'>
      <parent>base_link</parent>
      <child>left_track_link</child>
    </joint>
    <joint name='right_track_joint' type='fixed'>
      <parent>base_link</parent>
      <child>right_track_link</child>
    </joint>
    
    <!--rear_left_flipper-->
    <link name='rear_left_flipper_link'>
      <pose frame=''>-0.276 0.25 0 0 0 0</pose>
      <inertial>
        <pose frame=''>-0.16867 0.015987 0 0 0 0</pose>
        <mass>2.5</mass>
        <inertia>
          <ixx>0.002449</ixx>
          <ixy>0</ixy>
          <ixz>0</ixz>
          <iyy>0.02168</iyy>
          <iyz>0</iyz>
          <izz>0.019288</izz>
        </inertia>
      </inertial>
      <gravity>1</gravity>
      <velocity_decay/>
      <self_collide>0</self_collide>
      <kinematic>0</kinematic>
      <enable_wind>0</enable_wind>

      <collision name='rear_left_flipper_collision_large_wheel_collision'>
        <max_contacts>20</max_contacts>
        <pose frame=''>0 0.016 0 1.5708 0 0</pose>
        <geometry>
          <cylinder>
            <radius>0.09</radius>
            <length>0.038</length>
          </cylinder>
        </geometry>
        <surface>
          <friction>
            <ode>
              <mu>0.7</mu>
              <mu2>150</mu2>
              <fdir1>0 1 0</fdir1>
            </ode>
          </friction>
        </surface>
      </collision>
      <collision name='rear_left_flipper_collision_small_wheel_collision'>
        <max_contacts>20</max_contacts>
        <pose frame=''>-0.336 0.016 0 1.5708 0 0</pose>
        <geometry>
          <cylinder>
            <radius>0.09</radius>
            <length>0.038</length>
          </cylinder>
        </geometry>
        <surface>
          <friction>
            <ode>
              <mu>0.7</mu>
              <mu2>150</mu2>
              <fdir1>0 1 0</fdir1>
            </ode>
          </friction>
        </surface>
      </collision>
      <collision name='rear_left_flipper_collision_middle_bar_collision'>
        <max_contacts>20</max_contacts>
        <pose frame=''>-0.168 0.016 0 0 0 0</pose>
        <geometry>
          <box>
            <size>0.336 0.038 0.18</size>
          </box>
        </geometry>
        <surface>
          <friction>
            <ode>
              <mu>0.7</mu>
              <mu2>150</mu2>
              <fdir1>0 1 0</fdir1>
            </ode>
          </friction>
        </surface>
      </collision>
      <visual name='rear_left_flipper_visual'>
        <pose frame=''>0 0 0 0 0 0</pose>
        <geometry>
          <mesh>
            <scale>1 1 1</scale>
            <uri>model://NuBot_Pumbaa_v2/meshes/back_left_fin_link.STL</uri>
          </mesh>
        </geometry>
      </visual>
    </link>
    <joint name='rear_left_flipper_joint' type='revolute'>
      <child>rear_left_flipper_link</child>
      <parent>base_link</parent>
      <pose frame=''>0 0 0 0 0 0</pose>
      <axis>
        <xyz>0 1 0</xyz>
        <limit>
          <lower>-3</lower>
          <upper>3</upper>
          <effort>-1</effort>
          <velocity>0.3</velocity>
        </limit>
        <dynamics>
          <spring_reference>0</spring_reference>
          <spring_stiffness>0</spring_stiffness>
          <damping>10</damping>
          <friction>0</friction>
        </dynamics>
        <use_parent_model_frame>1</use_parent_model_frame>
      </axis>
      <physics>
        <ode>
          <implicit_spring_damper>1</implicit_spring_damper>
          <cfm_damping>1</cfm_damping>
          <limit>
            <cfm>0</cfm>
            <erp>0.2</erp>
          </limit>
        </ode>
      </physics>
    </joint>

    <!--rear_right_flipper-->
    <link name='rear_right_flipper_link'>
      <pose frame=''>-0.276 -0.25 0 0 0 0</pose>
      <inertial>
        <pose frame=''>-0.16867 -0.015987 0 0 0 0</pose>
        <mass>2.5</mass>
        <inertia>
          <ixx>0.002449</ixx>
          <ixy>0</ixy>
          <ixz>0</ixz>
          <iyy>0.02168</iyy>
          <iyz>0</iyz>
          <izz>0.019288</izz>
        </inertia>
      </inertial>
      <gravity>1</gravity>
      <velocity_decay/>
      <self_collide>1</self_collide>
      <kinematic>0</kinematic>
      <enable_wind>0</enable_wind>

      <collision name='rear_right_flipper_collision_large_wheel_collision'>
        <max_contacts>20</max_contacts>
        <pose frame=''>0 -0.016 0 1.5708 0 0</pose>
        <geometry>
          <cylinder>
            <radius>0.09</radius>
            <length>0.038</length>
          </cylinder>
        </geometry>
        <surface>
          <friction>
            <ode>
              <mu>0.7</mu>
              <mu2>150</mu2>
              <fdir1>0 1 0</fdir1>
            </ode>
          </friction>
        </surface>
      </collision>
      <collision name='rear_right_flipper_collision_small_wheel_collision'>
        <max_contacts>20</max_contacts>
        <pose frame=''>-0.336 -0.016 0 1.5708 0 0</pose>
        <geometry>
          <cylinder>
            <radius>0.09</radius>
            <length>0.038</length>
          </cylinder>
        </geometry>
        <surface>
          <friction>
            <ode>
              <mu>0.7</mu>
              <mu2>150</mu2>
              <fdir1>0 1 0</fdir1>
            </ode>
          </friction>
        </surface>
      </collision>
      <collision name='rear_right_flipper_collision_middle_bar_collision'>
        <max_contacts>20</max_contacts>
        <pose frame=''>-0.168 -0.016 0 0 0 -3.1416</pose>
        <geometry>
          <box>
            <size>0.336 0.038 0.18</size>
          </box>
        </geometry>
        <surface>
          <friction>
            <ode>
              <mu>0.7</mu>
              <mu2>150</mu2>
              <fdir1>0 1 0</fdir1>
            </ode>
          </friction>
        </surface>
      </collision>
      <visual name='rear_right_flipper_visual'>
        <pose frame=''>0 0 0 0 0 0</pose>
        <geometry>
          <mesh>
            <scale>1 1 1</scale>
            <uri>model://NuBot_Pumbaa_v2/meshes/back_right_fin_link.STL</uri>
          </mesh>
        </geometry>
      </visual>
    </link>
    <joint name='rear_right_flipper_joint' type='revolute'>
      <child>rear_right_flipper_link</child>
      <parent>base_link</parent>
      <pose frame=''>0 0 0 0 0 0</pose>
      <axis>
        <xyz>0 1 0</xyz>
        <limit>
          <lower>-3</lower>
          <upper>3</upper>
          <effort>-1</effort>
          <velocity>0.3</velocity>
        </limit>
        <dynamics>
          <spring_reference>0</spring_reference>
          <spring_stiffness>0</spring_stiffness>
          <damping>10</damping>
          <friction>0</friction>
        </dynamics>
        <use_parent_model_frame>1</use_parent_model_frame>
      </axis>
      <physics>
        <ode>
          <implicit_spring_damper>1</implicit_spring_damper>
          <cfm_damping>1</cfm_damping>
          <limit>
            <cfm>0</cfm>
            <erp>0.2</erp>
          </limit>
        </ode>
      </physics>
    </joint>

    <!--front_left_flipper-->
    <link name='front_left_flipper_link'>
      <pose frame=''>0.276 0.25 0 0 0 0</pose>
      <inertial>
        <pose frame=''>0.16867 0.015987 0 0 0 0</pose>
        <mass>2.5</mass>
        <inertia>
          <ixx>0.002449</ixx>
          <ixy>0</ixy>
          <ixz>0</ixz>
          <iyy>0.02168</iyy>
          <iyz>0</iyz>
          <izz>0.019288</izz>
        </inertia>
      </inertial>
      <gravity>1</gravity>
      <velocity_decay/>
      <self_collide>1</self_collide>
      <kinematic>0</kinematic>
      <enable_wind>0</enable_wind>

      <collision name='front_left_flipper_collision_large_wheel_collision'>
        <max_contacts>20</max_contacts>
        <pose frame=''>0 0.016 0 1.5708 0 0</pose>
        <geometry>
          <cylinder>
            <radius>0.09</radius>
            <length>0.038</length>
          </cylinder>
        </geometry>
        <surface>
          <friction>
            <ode>
              <mu>0.7</mu>
              <mu2>150</mu2>
              <fdir1>0 1 0</fdir1>
            </ode>
          </friction>
        </surface>
      </collision>
      <collision name='front_left_flipper_collision_small_wheel_collision'>
        <max_contacts>20</max_contacts>
        <pose frame=''>0.336 0.016 0 1.5708 0 0</pose>
        <geometry>
          <cylinder>
            <radius>0.09</radius>
            <length>0.038</length>
          </cylinder>
        </geometry>
        <surface>
          <friction>
            <ode>
              <mu>0.7</mu>
              <mu2>150</mu2>
              <fdir1>0 1 0</fdir1>
            </ode>
          </friction>
        </surface>
      </collision>
      <collision name='front_left_flipper_collision_middle_bar_collision'>
        <max_contacts>20</max_contacts>
        <pose frame=''>0.168 0.016 0 0 0 0</pose>
        <geometry>
          <box>
            <size>0.336 0.038 0.18</size>
          </box>
        </geometry>
        <surface>
          <friction>
            <ode>
              <mu>0.7</mu>
              <mu2>150</mu2>
              <fdir1>0 1 0</fdir1>
            </ode>
          </friction>
        </surface>
      </collision>
      <visual name='front_left_flipper_visual'>
        <pose frame=''>0 0 0 0 0 0</pose>
        <geometry>
          <mesh>
            <scale>1 1 1</scale>
            <uri>model://NuBot_Pumbaa_v2/meshes/front_left_fin_link.STL</uri>
          </mesh>
        </geometry>
      </visual>
    </link>
    <joint name='front_left_flipper_joint' type='revolute'>
      <child>front_left_flipper_link</child>
      <parent>base_link</parent>
      <pose frame=''>0 0 0 0 0 0</pose>
      <axis>
        <xyz>0 1 0</xyz>
        <limit>
          <lower>-3</lower>
          <upper>3</upper>
          <effort>-1</effort>
          <velocity>0.3</velocity>
        </limit>
        <dynamics>
          <spring_reference>0</spring_reference>
          <spring_stiffness>0</spring_stiffness>
          <damping>10</damping>
          <friction>0</friction>
        </dynamics>
        <use_parent_model_frame>1</use_parent_model_frame>
      </axis>
      <physics>
        <ode>
          <implicit_spring_damper>1</implicit_spring_damper>
          <cfm_damping>1</cfm_damping>
          <limit>
            <cfm>0</cfm>
            <erp>0.2</erp>
          </limit>
        </ode>
      </physics>
    </joint>

    <!--front_right_flipper-->
    <link name='front_right_flipper_link'>
      <pose frame=''>0.276 -0.25 0 0 0 0</pose>
      <inertial>
        <pose frame=''>0.16867 -0.015987 0 0 0 0</pose>
        <mass>2.5</mass>
        <inertia>
          <ixx>0.002449</ixx>
          <ixy>0</ixy>
          <ixz>0</ixz>
          <iyy>0.02168</iyy>
          <iyz>0</iyz>
          <izz>0.019288</izz>
        </inertia>
      </inertial>
      <gravity>1</gravity>
      <velocity_decay/>
      <self_collide>1</self_collide>
      <kinematic>0</kinematic>
      <enable_wind>0</enable_wind>

      <collision name='front_right_flipper_collision_large_wheel_collision'>
        <max_contacts>20</max_contacts>
        <pose frame=''>0 -0.016 0 1.5708 0 0</pose>
        <geometry>
          <cylinder>
            <radius>0.09</radius>
            <length>0.038</length>
          </cylinder>
        </geometry>
        <surface>
          <friction>
            <ode>
              <mu>0.7</mu>
              <mu2>150</mu2>
              <fdir1>0 1 0</fdir1>
            </ode>
          </friction>
        </surface>
      </collision>
      <collision name='front_right_flipper_collision_small_wheel_collision'>
        <max_contacts>20</max_contacts>
        <pose frame=''>0.336 -0.016 0 1.5708 0 0</pose>
        <geometry>
          <cylinder>
            <radius>0.09</radius>
            <length>0.038</length>
          </cylinder>
        </geometry>
        <surface>
          <friction>
            <ode>
              <mu>0.7</mu>
              <mu2>150</mu2>
              <fdir1>0 1 0</fdir1>
            </ode>
          </friction>
        </surface>
      </collision>
      <collision name='front_right_flipper_collision_middle_bar_collision'>
        <max_contacts>20</max_contacts>
        <pose frame=''>0.168 -0.016 0 0 0 -3.1416</pose>
        <geometry>
          <box>
            <size>0.336 0.038 0.18</size>
          </box>
        </geometry>
        <surface>
          <friction>
            <ode>
              <mu>0.7</mu>
              <mu2>150</mu2>
              <fdir1>0 1 0</fdir1>
            </ode>
          </friction>
        </surface>
      </collision>
      <visual name='front_right_flipper_link_visual'>
        <pose frame=''>0 0 0 0 0 0</pose>
        <geometry>
          <mesh>
            <scale>1 1 1</scale>
            <uri>model://NuBot_Pumbaa_v2/meshes/front_right_fin_link.STL</uri>
          </mesh>
        </geometry>
      </visual>
    </link>
    <joint name='front_right_flipper_joint' type='revolute'>
      <child>front_right_flipper_link</child>
      <parent>base_link</parent>
      <pose frame=''>0 0 0 0 0 0</pose>
      <axis>
        <xyz>0 1 0</xyz>
        <limit>
          <lower>-3</lower>
          <upper>3</upper>
          <effort>-1</effort>
          <velocity>0.3</velocity>
        </limit>
        <dynamics>
          <spring_reference>0</spring_reference>
          <spring_stiffness>0</spring_stiffness>
          <damping>10</damping>
          <friction>0</friction>
        </dynamics>
        <use_parent_model_frame>1</use_parent_model_frame>
      </axis>
      <physics>
        <ode>
          <implicit_spring_damper>1</implicit_spring_damper>
          <cfm_damping>1</cfm_damping>
          <limit>
            <cfm>0</cfm>
            <erp>0.2</erp>
          </limit>
        </ode>
      </physics>
    </joint>

    <plugin name='NuBot_Pumbaa_Gazebo_Plugin' filename='libnubot_pumbaa_plugin.so'>
      <!--The link tags of tracks-->
      <body>base_link</body>
      <left_track>left_track_link</left_track>
      <right_track>right_track_link</right_track>
      <left_flipper>front_left_flipper_link</left_flipper>
      <left_flipper>rear_left_flipper_link</left_flipper>
      <right_flipper>front_right_flipper_link</right_flipper>
      <right_flipper>rear_right_flipper_link</right_flipper>
      <!--The flippers' joint tag-->
      <front_left_flipper_j>front_left_flipper_joint</front_left_flipper_j>
      <rear_left_flipper_j>rear_left_flipper_joint</rear_left_flipper_j>
      <front_right_flipper_j>front_right_flipper_joint</front_right_flipper_j>
      <rear_right_flipper_j>rear_right_flipper_joint</rear_right_flipper_j>
      <!--The Mu/Mu2 of tracks, which influnce the simulating performance-->
      <track_mu>2</track_mu>
      <track_mu2>0.5</track_mu2>
      <!--The PID parameter of flippers position controll & initial position 1.5708 -->
      <flip_p>1500</flip_p>
      <flip_i>100</flip_i>
      <flip_d>0</flip_d>
      <flip_initial>1.0472</flip_initial>
      <!--The parameters of tracks-->
      <tracksSeparation>0.285</tracksSeparation>
      <steeringEfficiency>0.5</steeringEfficiency>
      <maxLinearSpeed>2.0</maxLinearSpeed>
      <maxAngularSpeed>1.5</maxAngularSpeed>
    </plugin>
  </model>
</sdf>
